#VRML_SIM R2022b utf8
# license: Apache License 2.0
# license url: http://www.apache.org/licenses/LICENSE-2.0
# This is a proto file for Webots for the Turtlebot4
# Extracted from: /home/omartinez/smartloc_ct/src/smartloc_ct/turtlebot4/turtlebot4_description/urdf/standard/tb4.urdf

PROTO Turtlebot4 [
  field  SFVec3f     translation     0 0 0
  field  SFRotation  rotation        0 0 1 0
  field  SFString    name            "Turtlebot4"  # Is `Robot.name`.
  field  SFString    controller      "void"        # Is `Robot.controller`.
  field  MFString    controllerArgs  []            # Is `Robot.controllerArgs`.
  field  SFString    customData      ""            # Is `Robot.customData`.
  field  SFBool      supervisor      FALSE         # Is `Robot.supervisor`.
  field  SFBool      synchronization TRUE          # Is `Robot.synchronization`.
  field  SFBool      selfCollision   FALSE         # Is `Robot.selfCollision`.
]
{
  Robot {
    translation IS translation
    rotation IS rotation
    controller IS controller
    controllerArgs IS controllerArgs
    customData IS customData
    supervisor IS supervisor
    synchronization IS synchronization
    selfCollision IS selfCollision
    children [
      Transform {
        translation 0.000000 0.000000 0.000000
        rotation 0.000000 0.000000 1.000000 1.570796
        children [
          DEF body_visual_visual CadShape {
            url "/opt/ros/humble/share/irobot_create_description/meshes/body_visual.dae"
          }
        ]
      }
      GPS {
        name "p3d gps"
      }
      InertialUnit {
        name "p3d inertial"
      }
      Gyro {
        name "p3d gyro"
      }
      Solid {
        translation 0.000000 0.000000 0.000000
        children [
          DEF bumper_visual_visual CadShape {
            url "/opt/ros/humble/share/irobot_create_description/meshes/bumper_visual.dae"
          }
        ]
        name "bump_front_center"
        boundingObject DEF bumper_collision Mesh {
          url "/opt/ros/humble/share/irobot_create_description/meshes/bumper_collision.dae"
        }
        physics Physics {
          density -1
          mass 0.100000
          centerOfMass [ 0.080000 0.000000 0.020000 ]
          inertiaMatrix [
            1.348375e-03 2.521737e-04 1.544253e-03
            4.543520e-08 1.443485e-06 -6.721000e-10
          ]
        }
      }
      SliderJoint {
        jointParameters JointParameters {
          axis 0.000000 0.000000 -1.000000
          dampingConstant 50.0
          staticFriction 0.1
        }
        device [
          LinearMotor {
            name "wheel_drop_left_joint"
            maxPosition 0.03
            maxForce 10000
          }
          PositionSensor {
            name "wheel_drop_left_joint_sensor"
          }
        ]
        endPoint Solid {
          translation 0.000000 0.116500 0.000000
          rotation -1.000000 0.000000 0.000000 1.570796
          children [
            HingeJoint {
              jointParameters HingeJointParameters {
                axis 0.000000 0.000000 1.000000
              }
              device [
                RotationalMotor {
                  name "left_wheel_joint"
                  maxTorque 10000
                  consumptionFactor -0.001
                  maxVelocity 6.67
                }
                PositionSensor {
                  name "left_wheel_joint_sensor"
                  resolution 0.00628
                }
              ]
              endPoint Solid {
                children [
                  Shape {
                    appearance DEF black PBRAppearance {
                      baseColor 0.100000 0.100000 0.100000
                      roughness 1.000000
                      metalness 0
                    }
                    geometry Cylinder {
                      radius 0.035750000000000004
                      height 0.015
                    }
                  }
                ]
                name "left_wheel"
                boundingObject Cylinder {
                  radius 0.035750000000000004
                  height 0.015
                }
                physics Physics {
                  density -1
                  mass 0.200000
                  centerOfMass [ 0.000000 0.000000 0.000000 ]
                  inertiaMatrix [
                    6.765313e-05 6.765313e-05 1.278063e-04
                    0.000000e+00 0.000000e+00 0.000000e+00
                  ]
                }
              }
            }
          ]
          name "wheel_drop_left"
          physics Physics {
            density -1
            mass 0.050000
            centerOfMass [ 0.000000 0.000000 0.000000 ]
            inertiaMatrix [
              2.083333e-05 2.083333e-05 2.083333e-05
              0.000000e+00 0.000000e+00 0.000000e+00
            ]
          }
        }
      }
      SliderJoint {
        jointParameters JointParameters {
          axis 0.000000 0.000000 -1.000000
          dampingConstant 50.0
          staticFriction 0.1
        }
        device [
          LinearMotor {
            name "wheel_drop_right_joint"
            maxPosition 0.03
            maxForce 10000
          }
          PositionSensor {
            name "wheel_drop_right_joint_sensor"
          }
        ]
        endPoint Solid {
          translation 0.000000 -0.116500 0.040200
          rotation -1.000000 0.000000 0.000000 1.570796
          children [
            HingeJoint {
              jointParameters HingeJointParameters {
                axis 0.000000 0.000000 1.000000
              }
              device [
                RotationalMotor {
                  name "right_wheel_joint"
                  maxTorque 10000
                  consumptionFactor -0.001
                  maxVelocity 6.67
                }
                PositionSensor {
                  name "right_wheel_joint_sensor"
                  resolution 0.00628
                }
              ]
              endPoint Solid {
                children [
                  Shape {
                    appearance USE black
                    geometry Cylinder {
                      radius 0.035750000000000004
                      height 0.015
                    }
                  }
                ]
                name "right_wheel"
                boundingObject Cylinder {
                  radius 0.035750000000000004
                  height 0.015
                }
                physics Physics {
                  density -1
                  mass 0.200000
                  centerOfMass [ 0.000000 0.000000 0.000000 ]
                  inertiaMatrix [
                    6.765313e-05 6.765313e-05 1.278063e-04
                    0.000000e+00 0.000000e+00 0.000000e+00
                  ]
                }
              }
            }
          ]
          name "wheel_drop_right"
          physics Physics {
            density -1
            mass 0.050000
            centerOfMass [ 0.000000 0.000000 0.000000 ]
            inertiaMatrix [
              2.083333e-05 2.083333e-05 2.083333e-05
              0.000000e+00 0.000000e+00 0.000000e+00
            ]
          }
        }
      }
      Solid {
        translation 0.125000 0.000000 0.012200
        rotation -1.000000 0.000000 0.000000 1.570796
        children [
          Shape {
            appearance USE black
            geometry Sphere {
              radius 0.01
            }
          }
        ]
        name "front_caster_link"
        boundingObject Sphere {
          radius 0.01
        }
        physics Physics {
          density -1
          mass 0.010000
          centerOfMass [ 0.000000 0.000000 0.000000 ]
          inertiaMatrix [
            4.000000e-07 4.000000e-07 4.000000e-07
            0.000000e+00 0.000000e+00 0.000000e+00
          ]
        }
      }
      Solid {
        translation 0.050613 0.043673 0.084400
        name "imu_link"
        physics Physics {
          density -1
          mass 0.010000
          centerOfMass [ 0.000000 0.000000 0.000000 ]
          inertiaMatrix [
            1.666667e-07 1.666667e-07 1.666667e-07
            0.000000e+00 0.000000e+00 0.000000e+00
          ]
        }
      }
      Solid {
        translation 0.101500 0.087000 0.009200
        rotation 0.000000 0.000000 -1.000000 0.785398
        name "mouse"
        physics Physics {
          density -1
          mass 0.010000
          centerOfMass [ 0.000000 0.000000 0.000000 ]
          inertiaMatrix [
            1.666667e-07 1.666667e-07 1.666667e-07
            0.000000e+00 0.000000e+00 0.000000e+00
          ]
        }
      }
      Solid {
        translation 0.060000 0.145000 0.019200
        rotation -0.641175 0.070786 0.764123 2.973271
        children [
          Lidar {
            name "cliff_side_left"
            fieldOfView 0.087266
            horizontalResolution 1
            numberOfLayers 1
            minRange 0.000100
            maxRange 0.150000
            resolution 1.000000
            near 0.000100
          }
        ]
        name "cliff_side_left"
        physics Physics {
          density -1
          mass 0.010000
          centerOfMass [ 0.000000 0.000000 0.000000 ]
          inertiaMatrix [
            1.666667e-07 1.666667e-07 1.666667e-07
            0.000000e+00 0.000000e+00 0.000000e+00
          ]
        }
      }
      Solid {
        translation 0.060000 -0.145000 0.019200
        rotation 0.641175 0.070786 -0.764123 2.973271
        children [
          Lidar {
            name "cliff_side_right"
            fieldOfView 0.087266
            horizontalResolution 1
            numberOfLayers 1
            minRange 0.000100
            maxRange 0.150000
            resolution 1.000000
            near 0.000100
          }
        ]
        name "cliff_side_right"
        physics Physics {
          density -1
          mass 0.010000
          centerOfMass [ 0.000000 0.000000 0.000000 ]
          inertiaMatrix [
            1.666667e-07 1.666667e-07 1.666667e-07
            0.000000e+00 0.000000e+00 0.000000e+00
          ]
        }
      }
      Solid {
        translation 0.160000 0.045000 0.019200
        rotation -0.453800 0.708225 0.540818 1.739558
        children [
          Lidar {
            name "cliff_front_left"
            fieldOfView 0.087266
            horizontalResolution 1
            numberOfLayers 1
            minRange 0.000100
            maxRange 0.150000
            resolution 1.000000
            near 0.000100
          }
        ]
        name "cliff_front_left"
        physics Physics {
          density -1
          mass 0.010000
          centerOfMass [ 0.000000 0.000000 0.000000 ]
          inertiaMatrix [
            1.666667e-07 1.666667e-07 1.666667e-07
            0.000000e+00 0.000000e+00 0.000000e+00
          ]
        }
      }
      Solid {
        translation 0.160000 -0.045000 0.019200
        rotation 0.453800 0.708225 -0.540818 1.739558
        children [
          Lidar {
            name "cliff_front_right"
            fieldOfView 0.087266
            horizontalResolution 1
            numberOfLayers 1
            minRange 0.000100
            maxRange 0.150000
            resolution 1.000000
            near 0.000100
          }
        ]
        name "cliff_front_right"
        physics Physics {
          density -1
          mass 0.010000
          centerOfMass [ 0.000000 0.000000 0.000000 ]
          inertiaMatrix [
            1.666667e-07 1.666667e-07 1.666667e-07
            0.000000e+00 0.000000e+00 0.000000e+00
          ]
        }
      }
      Solid {
        translation 0.154000 0.000000 0.057200
        children [
          Lidar {
            name "ir_intensity_front_center_left"
            fieldOfView 0.174533
            verticalFieldOfView 0.174533
            horizontalResolution 5
            numberOfLayers 5
            minRange 0.025000
            maxRange 0.200000
            resolution 1.000000
          }
        ]
        name "ir_intensity_front_center_left"
        physics Physics {
          density -1
          mass 0.010000
          centerOfMass [ 0.000000 0.000000 0.000000 ]
          inertiaMatrix [
            1.666667e-07 1.666667e-07 1.666667e-07
            0.000000e+00 0.000000e+00 0.000000e+00
          ]
        }
      }
      Solid {
        translation 0.139600 -0.065100 0.057200
        rotation 0.000000 0.000000 -1.000000 0.436000
        children [
          Lidar {
            name "ir_intensity_front_center_right"
            fieldOfView 0.174533
            verticalFieldOfView 0.174533
            horizontalResolution 5
            numberOfLayers 5
            minRange 0.025000
            maxRange 0.200000
            resolution 1.000000
          }
        ]
        name "ir_intensity_front_center_right"
        physics Physics {
          density -1
          mass 0.010000
          centerOfMass [ 0.000000 0.000000 0.000000 ]
          inertiaMatrix [
            1.666667e-07 1.666667e-07 1.666667e-07
            0.000000e+00 0.000000e+00 0.000000e+00
          ]
        }
      }
      Solid {
        translation 0.139600 0.065100 0.057200
        rotation 0.000000 0.000000 1.000000 0.436000
        children [
          Lidar {
            name "ir_intensity_front_left"
            fieldOfView 0.174533
            verticalFieldOfView 0.174533
            horizontalResolution 5
            numberOfLayers 5
            minRange 0.025000
            maxRange 0.200000
            resolution 1.000000
          }
        ]
        name "ir_intensity_front_left"
        physics Physics {
          density -1
          mass 0.010000
          centerOfMass [ 0.000000 0.000000 0.000000 ]
          inertiaMatrix [
            1.666667e-07 1.666667e-07 1.666667e-07
            0.000000e+00 0.000000e+00 0.000000e+00
          ]
        }
      }
      Solid {
        translation 0.099000 -0.118000 0.057200
        rotation 0.000000 0.000000 -1.000000 0.873000
        children [
          Lidar {
            name "ir_intensity_front_right"
            fieldOfView 0.174533
            verticalFieldOfView 0.174533
            horizontalResolution 5
            numberOfLayers 5
            minRange 0.025000
            maxRange 0.200000
            resolution 1.000000
          }
        ]
        name "ir_intensity_front_right"
        physics Physics {
          density -1
          mass 0.010000
          centerOfMass [ 0.000000 0.000000 0.000000 ]
          inertiaMatrix [
            1.666667e-07 1.666667e-07 1.666667e-07
            0.000000e+00 0.000000e+00 0.000000e+00
          ]
        }
      }
      Solid {
        translation 0.099000 0.118000 0.057200
        rotation 0.000000 0.000000 1.000000 0.873000
        children [
          Lidar {
            name "ir_intensity_left"
            fieldOfView 0.174533
            verticalFieldOfView 0.174533
            horizontalResolution 5
            numberOfLayers 5
            minRange 0.025000
            maxRange 0.200000
            resolution 1.000000
          }
        ]
        name "ir_intensity_left"
        physics Physics {
          density -1
          mass 0.010000
          centerOfMass [ 0.000000 0.000000 0.000000 ]
          inertiaMatrix [
            1.666667e-07 1.666667e-07 1.666667e-07
            0.000000e+00 0.000000e+00 0.000000e+00
          ]
        }
      }
      Solid {
        translation 0.039900 -0.148800 0.057200
        rotation 0.000000 0.000000 -1.000000 1.309000
        children [
          Lidar {
            name "ir_intensity_right"
            fieldOfView 0.174533
            verticalFieldOfView 0.174533
            horizontalResolution 5
            numberOfLayers 5
            minRange 0.025000
            maxRange 0.200000
            resolution 1.000000
          }
        ]
        name "ir_intensity_right"
        physics Physics {
          density -1
          mass 0.010000
          centerOfMass [ 0.000000 0.000000 0.000000 ]
          inertiaMatrix [
            1.666667e-07 1.666667e-07 1.666667e-07
            0.000000e+00 0.000000e+00 0.000000e+00
          ]
        }
      }
      Solid {
        translation 0.039900 0.148800 0.057200
        rotation 0.000000 0.000000 1.000000 1.309000
        children [
          Lidar {
            name "ir_intensity_side_left"
            fieldOfView 0.174533
            verticalFieldOfView 0.174533
            horizontalResolution 5
            numberOfLayers 5
            minRange 0.025000
            maxRange 0.200000
            resolution 1.000000
          }
        ]
        name "ir_intensity_side_left"
        physics Physics {
          density -1
          mass 0.010000
          centerOfMass [ 0.000000 0.000000 0.000000 ]
          inertiaMatrix [
            1.666667e-07 1.666667e-07 1.666667e-07
            0.000000e+00 0.000000e+00 0.000000e+00
          ]
        }
      }
      Solid {
        translation 0.153000 0.000000 0.099200
        name "ir_omni"
        physics Physics {
          density -1
          mass 0.010000
          centerOfMass [ 0.000000 0.000000 0.000000 ]
          inertiaMatrix [
            1.666667e-07 1.666667e-07 1.666667e-07
            0.000000e+00 0.000000e+00 0.000000e+00
          ]
        }
      }
      
  }
}
